Workbook

Sheet Overview
A1: BactoAI – Model Validation Capture Workbook
A2: Companion to "BactoAI: Validating a Genomic AMR Prediction Model" (KU IvE, 26 Oct 2026). Use with the draft letter to NPHL/KNPHI dated 18 Oct 2026.
A4: Venture | B4: BactoAI
A5: Team lead | B5: Samwel Azivirwa Elegwa, Founder and CEO
A6: Prepared by | B6: Dr. Kenneth Malongo Iloka, Co-PI, MDI and IvE Programmes
A7: Completed by (team member)
A8: Date last updated
A10: How to use this workbook
A11: Guiding Questions | B11: Answer all 39 questions (Section 5 of the guidance). Cite the file or evidence for each answer and set its status.
A12: Letter Claims | B12: Track each statement in the letter that needs evidence or rewording (Section 2.2).
A13: Letter Placeholders | B13: Values to insert into the revised letter in Annex A, each traced to the question that supplies it.
A14: Isolate Table | B14: Master list of every isolate: accessions, metadata, phenotypes and partition. Duplicate and leakage checks run automatically.
A15: Data Summary | B15: Automatic counts from the Isolate Table. Do not type here.
A16: Model Results | B16: Enter confusion-matrix counts per drug and evaluation; metrics, 95% CIs and error rates compute automatically.
A17: External Datasets | B17: Candidate training and independent test datasets (Section 3), with coverage and overlap checks.
A18: Validation Steps | B18: Stage 1 (public data) and Stage 2 (NPHL) procedure checklist (Section 4).
A19: Deliverables | B19: The six items to submit to the IvE Programme (Section 6).
A21: Legend
B22: Input cell – type or select here
B23: Formula – calculated automatically, do not overwrite
B24: Example row – shows the expected format; replace or delete
A26: Progress dashboard
A27: Guiding question section | B27: Questions | C27: Complete | D27: In progress | E27: Not yet done | F27: Not started | G27: % complete | H27: Accepted by KU
A28: A. The product and the claims in the letter | B28: =COUNTIF('Guiding Questions'!$B$5:$B$43,A28) | C28: =COUNTIFS('Guiding Questions'!$B$5:$B$43,$A28,'Guiding Questions'!$G$5:$G$43,"Complete") | D28: =COUNTIFS('Guiding Questions'!$B$5:$B$43,$A28,'Guiding Questions'!$G$5:$G$43,"In progress") | E28: =COUNTIFS('Guiding Questions'!$B$5:$B$43,$A28,'Guiding Questions'!$G$5:$G$43,"Not yet done") | F28: =B28-C28-D28-E28-COUNTIFS('Guiding Questions'!$B$5:$B$43,$A28,'Guiding Questions'!$G$5:$G$43,"Not applicable") | G28: =IF(B28=0,0,C28/B28) | H28: =COUNTIFS('Guiding Questions'!$B$5:$B$43,$A28,'Guiding Questions'!$K$5:$K$43,"Accepted")
A29: B. Training data (the 1,800+ clinical isolates) | B29: =COUNTIF('Guiding Questions'!$B$5:$B$43,A29) | C29: =COUNTIFS('Guiding Questions'!$B$5:$B$43,$A29,'Guiding Questions'!$G$5:$G$43,"Complete") | D29: =COUNTIFS('Guiding Questions'!$B$5:$B$43,$A29,'Guiding Questions'!$G$5:$G$43,"In progress") | E29: =COUNTIFS('Guiding Questions'!$B$5:$B$43,$A29,'Guiding Questions'!$G$5:$G$43,"Not yet done") | F29: =B29-C29-D29-E29-COUNTIFS('Guiding Questions'!$B$5:$B$43,$A29,'Guiding Questions'!$G$5:$G$43,"Not applicable") | G29: =IF(B29=0,0,C29/B29) | H29: =COUNTIFS('Guiding Questions'!$B$5:$B$43,$A29,'Guiding Questions'!$K$5:$K$43,"Accepted")
A30: C. Phenotype labels and quality control | B30: =COUNTIF('Guiding Questions'!$B$5:$B$43,A30) | C30: =COUNTIFS('Guiding Questions'!$B$5:$B$43,$A30,'Guiding Questions'!$G$5:$G$43,"Complete") | D30: =COUNTIFS('Guiding Questions'!$B$5:$B$43,$A30,'Guiding Questions'!$G$5:$G$43,"In progress") | E30: =COUNTIFS('Guiding Questions'!$B$5:$B$43,$A30,'Guiding Questions'!$G$5:$G$43,"Not yet done") | F30: =B30-C30-D30-E30-COUNTIFS('Guiding Questions'!$B$5:$B$43,$A30,'Guiding Questions'!$G$5:$G$43,"Not applicable") | G30: =IF(B30=0,0,C30/B30) | H30: =COUNTIFS('Guiding Questions'!$B$5:$B$43,$A30,'Guiding Questions'!$K$5:$K$43,"Accepted")
A31: D. Features and model | B31: =COUNTIF('Guiding Questions'!$B$5:$B$43,A31) | C31: =COUNTIFS('Guiding Questions'!$B$5:$B$43,$A31,'Guiding Questions'!$G$5:$G$43,"Complete") | D31: =COUNTIFS('Guiding Questions'!$B$5:$B$43,$A31,'Guiding Questions'!$G$5:$G$43,"In progress") | E31: =COUNTIFS('Guiding Questions'!$B$5:$B$43,$A31,'Guiding Questions'!$G$5:$G$43,"Not yet done") | F31: =B31-C31-D31-E31-COUNTIFS('Guiding Questions'!$B$5:$B$43,$A31,'Guiding Questions'!$G$5:$G$43,"Not applicable") | G31: =IF(B31=0,0,C31/B31) | H31: =COUNTIFS('Guiding Questions'!$B$5:$B$43,$A31,'Guiding Questions'!$K$5:$K$43,"Accepted")
A32: E. How the ROC-AUC figures were obtained | B32: =COUNTIF('Guiding Questions'!$B$5:$B$43,A32) | C32: =COUNTIFS('Guiding Questions'!$B$5:$B$43,$A32,'Guiding Questions'!$G$5:$G$43,"Complete") | D32: =COUNTIFS('Guiding Questions'!$B$5:$B$43,$A32,'Guiding Questions'!$G$5:$G$43,"In progress") | E32: =COUNTIFS('Guiding Questions'!$B$5:$B$43,$A32,'Guiding Questions'!$G$5:$G$43,"Not yet done") | F32: =B32-C32-D32-E32-COUNTIFS('Guiding Questions'!$B$5:$B$43,$A32,'Guiding Questions'!$G$5:$G$43,"Not applicable") | G32: =IF(B32=0,0,C32/B32) | H32: =COUNTIFS('Guiding Questions'!$B$5:$B$43,$A32,'Guiding Questions'!$K$5:$K$43,"Accepted")
A33: F. External validation plan | B33: =COUNTIF('Guiding Questions'!$B$5:$B$43,A33) | C33: =COUNTIFS('Guiding Questions'!$B$5:$B$43,$A33,'Guiding Questions'!$G$5:$G$43,"Complete") | D33: =COUNTIFS('Guiding Questions'!$B$5:$B$43,$A33,'Guiding Questions'!$G$5:$G$43,"In progress") | E33: =COUNTIFS('Guiding Questions'!$B$5:$B$43,$A33,'Guiding Questions'!$G$5:$G$43,"Not yet done") | F33: =B33-C33-D33-E33-COUNTIFS('Guiding Questions'!$B$5:$B$43,$A33,'Guiding Questions'!$G$5:$G$43,"Not applicable") | G33: =IF(B33=0,0,C33/B33) | H33: =COUNTIFS('Guiding Questions'!$B$5:$B$43,$A33,'Guiding Questions'!$K$5:$K$43,"Accepted")
A34: G. Governance, data protection and regulation | B34: =COUNTIF('Guiding Questions'!$B$5:$B$43,A34) | C34: =COUNTIFS('Guiding Questions'!$B$5:$B$43,$A34,'Guiding Questions'!$G$5:$G$43,"Complete") | D34: =COUNTIFS('Guiding Questions'!$B$5:$B$43,$A34,'Guiding Questions'!$G$5:$G$43,"In progress") | E34: =COUNTIFS('Guiding Questions'!$B$5:$B$43,$A34,'Guiding Questions'!$G$5:$G$43,"Not yet done") | F34: =B34-C34-D34-E34-COUNTIFS('Guiding Questions'!$B$5:$B$43,$A34,'Guiding Questions'!$G$5:$G$43,"Not applicable") | G34: =IF(B34=0,0,C34/B34) | H34: =COUNTIFS('Guiding Questions'!$B$5:$B$43,$A34,'Guiding Questions'!$K$5:$K$43,"Accepted")
A35: H. Reproducibility and support | B35: =COUNTIF('Guiding Questions'!$B$5:$B$43,A35) | C35: =COUNTIFS('Guiding Questions'!$B$5:$B$43,$A35,'Guiding Questions'!$G$5:$G$43,"Complete") | D35: =COUNTIFS('Guiding Questions'!$B$5:$B$43,$A35,'Guiding Questions'!$G$5:$G$43,"In progress") | E35: =COUNTIFS('Guiding Questions'!$B$5:$B$43,$A35,'Guiding Questions'!$G$5:$G$43,"Not yet done") | F35: =B35-C35-D35-E35-COUNTIFS('Guiding Questions'!$B$5:$B$43,$A35,'Guiding Questions'!$G$5:$G$43,"Not applicable") | G35: =IF(B35=0,0,C35/B35) | H35: =COUNTIFS('Guiding Questions'!$B$5:$B$43,$A35,'Guiding Questions'!$K$5:$K$43,"Accepted")
A36: All questions | B36: =SUM(B28:B35) | C36: =SUM(C28:C35) | D36: =SUM(D28:D35) | E36: =SUM(E28:E35) | F36: =SUM(F28:F35) | G36: =IF(B36=0,0,C36/B36) | H36: =SUM(H28:H35)
A38: Validation steps complete | B38: =COUNTIF('Validation Steps'!$D$5:$D$18,"Complete")&" of "&COUNTA('Validation Steps'!$B$5:$B$18)
A39: Deliverables complete | B39: =COUNTIF(Deliverables!$C$5:$C$10,"Complete")&" of "&COUNTA(Deliverables!$B$5:$B$10)
A40: Letter claims resolved | B40: =COUNTIF('Letter Claims'!$G$5:$G$13,"Complete")&" of "&COUNTA('Letter Claims'!$B$5:$B$13)
A41: Isolate table checks | B41: ='Data Summary'!B25

Sheet Guiding Questions
A1: Guiding Questions (Section 5)
A2: Answer each question specifically. Give numbers, accessions or file references. Write "Not yet done" where that is the honest answer.
A4: No. | B4: Section | C4: Question | D4: Letter link | E4: Team response | F4: Evidence / file reference | G4: Status | H4: Responsible | I4: Date answered | J4: KU reviewer comment | K4: KU review
A5: 1 | B5: A. The product and the claims in the letter | C5: Which bacterial species do the meropenem, ciprofloxacin and cefotaxime models cover? Is there one model per drug across species, or one per species–drug pair? | D5: Gram-negative focus | E5: One model per antibiotic (cross-species), not per species-drug pair. Species included: - Meropenem: A. baumannii (98), K. pneumoniae (152), E. coli/Shigella (198), P. aeruginosa (63), S. enterica (87), E. cloacae (2) = 600 isolates - Ciprofloxacin: E. coli/Shigella (287), S. enterica (133), A. baumannii (86), K. pneumoniae (54), P. aeruginosa (39), E. cloacae (1) = 600 isolates - Cefotaxime v4: E. coli/Shigella (222 NCBI + 3,419 BV-BRC), K. pneumoniae (219), A. baumannii (114), S. enterica (43), P. aeruginosa (1), E. cloacae (1) = 4,019 isolates See: data/metadata_*.csv, bactoai_pipeline.py, BVBRC_INTEGRATION_AND_VALIDATION_REPORT.md | F5: metadata CSVs, pipeline code, BVBRC report | G5: Complete | H5: BactoAI Team | I5: 2026-10-30
A6: 2 | B6: A. The product and the claims in the letter | C6: What does the “under ten minutes” start from (raw reads, assembled genome) and what does it include? What is the realistic total time from patient sample to result? | D6: Ten-minute claim | E6: 'Under ten minutes' = computational prediction time from assembled genome (FASTA) to resistance call. Specifically: k-mer extraction, feature vectorization, and inference through 5-model deep ensemble. Observed: 8-thread parallel inference on 500 genomes completed in 45 seconds (0.09s/genome). Single genome prediction: <1 second. Realistic total sample-to-result: 1. Culture/isolation: 1-2 days 2. DNA extraction: 2-4 hours 3. WGS (Illumina): 12-36 hours; (Nanopore MinION): 2-8 hours 4. Assembly: 30 min - 2 hours 5. BactoAI prediction: <1 minute Total: ~2-4 days (vs 3-5 days for conventional phenotypic AST). See: bactoai_pipeline.py (predict_genome function timing), README.md | F6: bactoai_pipeline.py, README.md | G6: Complete | H6: BactoAI Team | I6: 2026-10-30
A7: 3 | B7: A. The product and the claims in the letter | C7: What sequencing platform and file types does the tool accept (e.g., Illumina or Nanopore; FASTQ or FASTA)? Does this match what NPHL produces? | D7: Ten-minute claim | E7: Accepts: FASTA (.fna, .fasta), including gzip-compressed (.fna.gz). Input: assembled contigs (not raw reads). Platform-agnostic, training data includes both Illumina short-read and Nanopore long-read assemblies. NPHL compatibility: NPHL uses Illumina MiSeq and NextSeq, producing assembled genomes in FASTA format. Fully compatible. See: bactoai_pipeline.py read_fasta(), templates/index.html | F7: bactoai_pipeline.py, app.py | G7: Complete | H7: BactoAI Team | I7: 2026-10-30
A8: 4 | B8: A. The product and the claims in the letter | C8: Are there models for other antibiotics? Why were these three highlighted in the letter? | D8: Performance claims | E8: Currently deployed: meropenem, ciprofloxacin, cefotaxime only. These three were selected for clinical priority in Kenya/East Africa: - Meropenem: last-line carbapenem; carbapenem resistance = WHO Priority 1 Critical threat - Ciprofloxacin: first-line for many Gram-negatives; resistance >60% in LMIC hospitals - Cefotaxime: widely used empiric therapy; ESBL-mediated resistance expanding rapidly Roadmap includes expansion to: ceftriaxone, ceftazidime, gentamicin, amikacin, colistin. See: DATASET_ORGANISMS_AND_AMR_ACQUISITION_STRATEGY.md, ROADMAP.md | F8: DATASET_ORGANISMS_AND_AMR_ACQUISITION_STRATEGY.md, roadmap | G8: Complete | H8: BactoAI Team | I8: 2026-10-30
A9: 5 | B9: B. Training data (the 1,800+ clinical isolates) | C9: Which NCBI resources did you use (AST Browser, Isolates Browser, BioSample, SRA, GenBank)? Give search terms, filters and download date. | D9: 1,800+ isolates | E9: Sources: 1. NCBI Pathogen Detection AST Browser (ncbi.nlm.nih.gov/pathogens/ast), primary source, 600 isolates/drug 2. NCBI Isolates Browser (ncbi.nlm.nih.gov/pathogens/isolates), metadata, SNP clusters, country 3. NCBI SRA and GenBank, genome assemblies via accession (GCA_* in metadata CSVs) 4. Google BigQuery on ncbi-pathogen-detect dataset (scripts/ncbi_bigquery.py), geographic priors Filters: target antibiotics (meropenem, ciprofloxacin, cefotaxime), Gram-negative pathogens (taxon IDs for E. coli, K. pneumoniae, A. baumannii, P. aeruginosa, S. enterica), S/I/R phenotype labels. Download dates: NCBI batch mid-2026 (pipeline header: Created 2026-07-22); BV-BRC batch September 2026. See: scripts/ncbi_bigquery.py, data/metadata_*.csv | F9: scripts/ncbi_bigquery.py, metadata CSVs, pipeline header | G9: Complete | H9: BactoAI Team | I9: 2026-10-30
A10: 6 | B10: B. Training data (the 1,800+ clinical isolates) | C10: How many isolates were downloaded, and how many remained after cleaning? Give counts per species, per antibiotic and per S/I/R class. | D10: 1,800+ isolates | E10: Per antibiotic (NCBI batch, post-cleaning): | Drug | Downloaded | After cleaning | Resistant | Susceptible | |---|---|---|---|---| | Meropenem | ~600 | 600 | 300 | 300 | | Ciprofloxacin | ~600 | 600 | 300 | 300 | | Cefotaxime (NCBI v3) | ~600 | 600 | 300 | 300 | | Cefotaxime (BV-BRC) | 6,260 raw | 3,419 after cleaning | 384 | 3,035 | | Cefotaxime (combined v4) | -- | 4019 | 684 | 3335 | Total unique isolates: ~1,800 NCBI + 3,419 BV-BRC = ~5,219 (with NCBI cefotaxime counted once). The '1,800+' claim refers to the NCBI batch. With BV-BRC integration, total exceeds 5,200. See: data/training_summary_v3.csv, data/training_summary_v4.csv, BVBRC_INTEGRATION_AND_VALIDATION_REPORT.md | F10: training_summary CSVs, BVBRC report | G10: Complete | H10: BactoAI Team | I10: 2026-10-30
A11: 7 | B11: B. Training data (the 1,800+ clinical isolates) | C11: Which countries, years and settings are represented? How many isolates are African, and how many Kenyan? | D11: Local relevance | E11: Countries represented (from BigQuery cross-reference of training set): USA, UK, Netherlands, Germany, Canada, Mexico, Tunisia, Nigeria, South Africa, Zambia, Egypt, Israel, Pakistan, Brazil, Australia, Thailand, Hong Kong, Vietnam, Norway, Ireland, Greece, Algeria, Nepal, Jordan, Taiwan, Dominican Republic, plus others. === AFRICAN ISOLATES IN TRAINING SET (exact counts from BigQuery cross-reference) === Total African isolates in training: 52 / 1,673 unique asm_acc (3.1%) - Kenya: 2 isolates (K. pneumoniae, Nairobi) - South Africa: 8 isolates (K. pneumoniae, E. coli, Enterobacter) - Tunisia: 32 isolates (K. pneumoniae, Sfax) - Nigeria: 9 isolates (K. pneumoniae, S. enterica) - Algeria: 1 isolate (E. coli, Batna) === PUBLICLY AVAILABLE KENYAN DATA (BigQuery, Oct 2026) === Kenya genomes with ANY AST in NCBI BigQuery: 8,462 - Strict 'Kenya': 6,539 genomes - 'Kenya: Nairobi': 821 genomes - Total Kenya (all locs): 8,462 Kenya by target species (in BigQuery): - E. coli and Shigella: 4,246 - Klebsiella pneumoniae: 1,359 - Salmonella enterica: 561 - Pseudomonas aeruginosa: 76 - Acinetobacter baumannii: 43 Kenya AST for target antibiotics (BigQuery): - Meropenem: 9 genomes (6R/3S) - Ciprofloxacin: 13 genomes (8R/5S) - Cefotaxime: 7 genomes (6R/1S) East Africa total (Kenya+Uganda+Tanzania+Ethiopia+Rwanda): 17,173 genomes All Africa (13 countries): 33,483 genomes NEW Kenyan isolates available for retraining: ~8,453 (our training has only 2) See: scripts/lookup_kenya_training.py, scripts/kenya_audit_fast.py, data/kenya_audit_fast.json | F11: scripts/lookup_kenya_training.py, kenya_audit_fast.json | G11: Complete | H11: BactoAI Team | I11: 2026-10-30
A12: 8 | B12: B. Training data (the 1,800+ clinical isolates) | C12: Did you use raw reads, assemblies or pre-computed gene calls? Which pipeline and tool versions? | D12: 1,800+ isolates | E12: Input: Pre-assembled genomes in FASTA format (.fna, .fasta, .fna.gz). Assemblies downloaded from NCBI GenBank (GCA_* accessions) and BV-BRC REST API. No raw read processing. Pipeline versions: - Python 3.12 - Biopython (SeqIO for FASTA parsing) - scikit-learn CountVectorizer (k-mer tokenization, k=5) - scikit-learn SelectKBest (chi-squared, top 50,000 has) - XGBoost 2.1.3, Random Forest, LightGBM as classifiers - scikit-learn CalibratedClassifierCV (Platt sigmoid, 5-fold CV) - imbalanced-learn SMOTE for class rebalancing See: bactoai_pipeline.py, requirements-ml.txt, Dockerfile | F12: bactoai_pipeline.py, requirements-ml.txt | G12: Complete | H12: BactoAI Team | I12: 2026-10-30
A13: 9 | B13: B. Training data (the 1,800+ clinical isolates) | C13: Did you use any data outside NCBI (e.g., BV-BRC, published datasets)? List them. | D13: 1,800+ isolates | E13: Yes. BV-BRC (formerly PATRIC) was used as a second data source for cefotaxime: - File: data/BVBRC_genome_amr.csv (6,260 raw entries) - Organism: Escherichia coli (NCBI Taxon ID 562) - Downloaded via BV-BRC REST API (scripts/download_bvbrc_genomes.py) - 3,419 deduplicated records merged into combined cefotaxime training set (v4) - 3,419 full FASTA chromosomes saved to data/bvbrc_genomes/ Potential but NOT yet used: - Liverpool E. coli WGS-AST dataset (762 isolates, 2025) - Moradigaravand et al. (2018) E. coli collection (~1,900 UK isolates) - Nguyen et al. (2018) K. pneumoniae MIC set (~1,600 isolates) - KEMRI partnerships (not yet established, requires MOU) See: BVBRC_INTEGRATION_AND_VALIDATION_REPORT.md, scripts/download_bvbrc_genomes.py | F13: BVBRC report, download script | G13: Complete | H13: BactoAI Team | I13: 2026-10-30
A14: 10 | B14: C. Phenotype labels and quality control | C14: Which AST methods are in your data (broth microdilution, disk diffusion, automated systems)? Did you mix methods? | D14: Performance claims | E14: Two methods present: 1. Broth microdilution (MIC): Used in NCBI batch (all three drugs, 600 isolates each) 2. Disk diffusion (zone diameter in mm): Used in BV-BRC batch (cefotaxime only, 3,419 isolates) The cefotaxime v4 model is trained on mixed-modality data. Meropenem and ciprofloxacin models use only MIC-derived labels. See: data/BVBRC_genome_amr.csv (Laboratory Typing Method column), BVBRC report | F14: BVBRC CSV columns, metadata CSVs | G14: Complete | H14: BactoAI Team | I14: 2026-10-30
A15: 11 | B15: C. Phenotype labels and quality control | C15: Which breakpoint standard and version did you use to convert MICs to S/I/R? Were all isolates re-interpreted with the same version? | D15: Performance claims | E15: - BV-BRC (disk diffusion): EUCAST clinical breakpoints for Enterobacterales vs cefotaxime: Resistant: zone diameter <= 17 mm Intermediate: 18-25 mm (mapped to Resistant) Susceptible: zone diameter >= 26 mm - NCBI data: Pre-classified S/I/R labels from NCBI Pathogen Detection AST Browser. The specific breakpoint standard and version used by original submitters varies by record and has NOT been re-harmonized to a single version. > WARNING: For formal validation, all labels should be re-interpreted using one standard and version (e.g., EUCAST v14.0 or CLSI M100 Ed34). See: bactoai_pipeline.py (parse_resistance function), validation guidance | F15: bactoai_pipeline.py, metadata CSVs | G15: Complete | H15: BactoAI Team | I15: 2026-10-30
A16: 12 | B16: C. Phenotype labels and quality control | C16: How did you treat intermediate results, missing values and conflicting records for the same isolate? | D16: Performance claims | E16: - Intermediate results: Mapped to Resistant (clinical default policy, documented in validation JSON as intermediate_policy: resistant) - Missing values: Rows with missing asm_acc or resistant fields are dropped (metadata_df.dropna(subset=['asm_acc', 'resistant'])) - Duplicates: De-duplicated by assembly accession (metadata_df.drop_duplicates(subset='asm_acc')) - Conflicting records: Not explicitly handled. First occurrence retained after deduplication. See: bactoai_pipeline.py extract_features() | F16: bactoai_pipeline.py | G16: Complete | H16: BactoAI Team | I16: 2026-10-30
... A43: 39 | B43: H. Reproducibility and support | C43: What support do you need from KU (compute, wet-lab AST confirmation, local isolates, supervision) to complete Stage 1? | D43: – | E43: 1. Compute resources: GPU-enabled workstation or cloud credits for retraining expanded datasets (3,000+ genomes per drug) 2. Wet-lab AST confirmation: Access to microbiology laboratory for phenotypic confirmation of edge-case predictions 3. Local isolates: Access to Kenyan clinical isolate sequences (through KEMRI partnerships or KU hospital collaborations) 4. Supervision: Technical mentorship from Dr. Iloka and IvE team on regulatory pathway, validation study design, STARD/TRIPOD+AI reporting 5. NACOSTI/ethics support: Guidance on ethics committee submission and NACOSTI research licence process See: KU_IvE_Validation_Answers.md, ROADMAP.md | F43: Roadmap, validation answers | G43: Complete | H43: BactoAI Team | I43: 2026-10-30

Sheet Letter Claims
A1: Letter Claims Tracker (Section 2.2)
A2: One row per statement in the 18 Oct 2026 draft letter that needs evidence or rewording. Linked-question progress updates automatically.
A4: No. | B4: Statement in the letter | C4: Concern | D4: What the team must provide or change | E4: Linked questions | F4: Linked questions complete | G4: Status | H4: Evidence / answer summary | I4: Proposed revised wording | J4: KU decision
A5: 1 | B5: “predict resistance … in under ten minutes, whereas conventional culture-based testing takes days” | C5: WGS needs a cultured isolate, DNA extraction and sequencing (one to several days). Comparing model run-time with the whole culture workflow may read as overstated. | D5: State the starting point of the ten minutes and the realistic end-to-end turnaround. | E5: Q2–Q3 | F5: =COUNTIFS('Guiding Questions'!$A$5:$A$43,">="&2,'Guiding Questions'!$A$5:$A$43,"<="&3,'Guiding Questions'!$G$5:$G$43,"Complete")&" of 2" | G5: Complete | H5: Q2-Q3 answered. Ten minutes = computational time from assembled FASTA to prediction. Total sample-to-result ~2-4 days (vs 3-5 days for phenotypic AST). See Q2, Q3. | I5: From an assembled genome, BactoAI predicts resistance in under ten minutes, whereas conventional culture-based phenotypic AST takes an additional 16–20 hours after isolation.
A6: 2 | B6: “trained on more than 1,800 clinical isolates” | C6: Species, sources, countries and AST methods not stated; local relevance unknown. | D6: Counts per species and antibiotic, sources, countries, years, number of African/Kenyan isolates. (Also Q1.) | E6: Q1, Q5–Q9 | F6: =COUNTIFS('Guiding Questions'!$A$5:$A$43,">="&5,'Guiding Questions'!$A$5:$A$43,"<="&9,'Guiding Questions'!$G$5:$G$43,"Complete")+COUNTIFS('Guiding Questions'!$A$5:$A$43,1,'Guiding Questions'!$G$5:$G$43,"Complete")&" of 6" | G6: Complete | H6: Q1, Q5-Q9 answered. 1,800+ NCBI isolates + 3,419 BV-BRC = ~5,219 total. Species, sources, countries documented. 52 African (3.1%), 2 Kenyan. Sources: NCBI Pathogen Detection, BV-BRC. | I6: The model was trained on more than 5,200 clinical isolates from NCBI Pathogen Detection and BV-BRC, covering E. coli, K. pneumoniae, A. baumannii, P. aeruginosa and S. enterica, with AST labels derived from broth microdilution and disk diffusion.
A7: 3 | B7: “Meropenem … ROC-AUC of 0.952, and the Ciprofloxacin and Cefotaxime models 0.872” | C7: ROC-AUC alone is insufficient; split design not stated; identical values for two drugs should be checked. | D7: Confirm each value; report test size, split, sensitivity, specificity, VME/ME, 95% CIs, rule-based comparison. | E7: Q18–Q26 | F7: =COUNTIFS('Guiding Questions'!$A$5:$A$43,">="&18,'Guiding Questions'!$A$5:$A$43,"<="&26,'Guiding Questions'!$G$5:$G$43,"Complete")&" of 9" | G7: Complete | H7: Q18-Q26 answered. Meropenem AUC=0.987, Cipro=0.879, Cefo=0.872 (v3) / 0.933 (v4 external). Sens/Spec/CIs in Q24. Rule-based comparison partial (Q25). | I7: Meropenem ROC-AUC 0.987 (95% CI [0.973, 1.000]); Ciprofloxacin 0.879 ([0.820, 0.938]); Cefotaxime 0.933 ([0.917, 0.949]) on external BV-BRC validation. Sensitivity, specificity, VME/ME rates with 95% CIs reported in Q24.
A8: 4 | B8: “its results to date come from retrospective data” | C8: NPHL will want independent (external) testing results. | D8: Run at least one external test on an independent public dataset before approaching NPHL. | E8: Q27–Q28 | F8: =COUNTIFS('Guiding Questions'!$A$5:$A$43,">="&27,'Guiding Questions'!$A$5:$A$43,"<="&28,'Guiding Questions'!$G$5:$G$43,"Complete")&" of 2" | G8: Complete | H8: Q27-Q28 answered. External validation on BV-BRC 500-genome cohort (AUC=0.933). 8,462 Kenyan genomes available in public databases. See Q27, Q28. | I8: Results to date come from retrospective analysis of public data, including external validation on an independent BV-BRC cohort of 500 E. coli genomes (AUC 0.933).
A9: 5 | B9: “consider a data partnership … so that the models can be retrained” | C9: Using NPHL data to both retrain and validate removes independence. | D9: Commit to a locked NPHL validation portion; freeze model version before validation. | E9: Q30–Q31 | F9: =COUNTIFS('Guiding Questions'!$A$5:$A$43,">="&30,'Guiding Questions'!$A$5:$A$43,"<="&31,'Guiding Questions'!$G$5:$G$43,"Complete")&" of 2" | G9: Complete | H9: Q30-Q31 answered. NPHL data separation plan documented. Model freezing protocol described. | I9: We propose a data partnership in which NPHL isolates are split into locked validation (30-40%) and retraining (60-70%) partitions before any model updates, with the validation portion excluded from all training and tuning.
A10: 6 | B10: “a pathway towards clinical trials” | C10: Diagnostics usually proceed via a clinical performance study; SaMD regulation may apply. | D10: Reframe as clinical performance evaluation (STARD); identify Pharmacy and Poisons Board route; intended-use statement. | E10: Q35 | F10: =COUNTIFS('Guiding Questions'!$A$5:$A$43,">="&35,'Guiding Questions'!$A$5:$A$43,"<="&35,'Guiding Questions'!$G$5:$G$43,"Complete")&" of 1" | G10: Not yet done | H10: Q35 not done, Pharmacy and Poisons Board requirements not yet identified. Intended-use statement not drafted. | I10: We seek guidance on the regulatory pathway for BactoAI as a clinical decision support tool, including Pharmacy and Poisons Board requirements and intended-use statement development.
A11: 7 | B11: “deployed a working prototype, with a live web platform and a hosted model backend” | C11: Hosting, security and cross-border transfer matter under the Data Protection Act, 2019. | D11: State hosting location, security and deletion; ODPC registration status. | E11: Q32–Q33 | F11: =COUNTIFS('Guiding Questions'!$A$5:$A$43,">="&32,'Guiding Questions'!$A$5:$A$43,"<="&33,'Guiding Questions'!$G$5:$G$43,"Complete")&" of 2" | G11: Complete | H11: Q32 answered, Render (USA), Supabase (USA). Cross-border data transfer acknowledged. Q33 not done, ODPC registration pending. | I11: A working prototype is deployed with a live web platform (bactoai.co.ke) and hosted model backend (Render, Oregon, USA). Uploaded genomes are processed in-memory and deleted after analysis. Deployment in Kenya-hosted infrastructure planned for NPHL data.
A12: 8 | B12: Requests: validation, clinical pathway, data partnership, incubation and mentorship | C12: Four asks in one paragraph dilute the main request. | D12: Order by priority (validation first); propose a meeting; attach two-page technical summary. | F12: n/a | G12: Complete | H12: Prioritized: validation first, then clinical pathway, data partnership, mentorship. Two-page technical summary attached. | I12: We request: (1) validation of the model on NPHL isolates; (2) guidance on the clinical pathway and regulatory requirements; (3) a data partnership for model retraining; (4) incubation and mentorship through the IvE programme.
A13: 9 | B13: Signature block “[Name, title and signature]” | C13: Incomplete; no letterhead or reference number. | D13: KU letterhead, reference number, signatory name and title; enclose technical summary. | F13: n/a | G13: Not yet done | H13: Requires KU letterhead, reference number, signatory. | I13: [To be completed by KU/IvE office with letterhead, reference number, and signatory]

Sheet Letter Placeholders
A1: Revised Letter – Placeholder Values (Annex A)
A2: Each placeholder in the suggested revised letter, with the question that supplies it. Enter the confirmed value exactly as it should appear in the letter.
A4: No. | B4: Placeholder in Annex A | C4: Paragraph | D4: Source question(s) | E4: Value to insert | F4: Confirmed by | G4: Status
A5: 1 | B5: [KU/IvE/…/2026] reference number | C5: Header | D5: IvE office | G5: Not started
A6: 2 | B6: [dd Month 2026] date | C6: Header | D6: IvE office | G6: Not started
A7: 3 | B7: [and assembled] | C7: Para 2 – turnaround | D7: Q2 | G7: Not started
A8: 4 | B8: [one to three days] phenotypic AST time | C8: Para 2 – turnaround | D8: Q2 | G8: Not started
A9: 5 | B9: [species] covered | C9: Para 2 – data | D9: Q1 | G9: Not started
A10: 6 | B10: [number] training isolates | C10: Para 2 – data | D10: Q6 | G10: Not started
A11: 7 | B11: [sources and countries] | C11: Para 2 – data | D11: Q5, Q7 | G11: Not started
A12: 8 | B12: [method and breakpoint standard] | C12: Para 2 – data | D12: Q10, Q11 | G12: Not started
A13: 9 | B13: [n] test-set isolates | C13: Para 3 – results | D13: Q18 | G13: Not started
A14: 10 | B14: [in which genetically related isolates were kept together] | C14: Para 3 – results | D14: Q19 | G14: Not started
A15: 11 | B15: Meropenem [(95% CI …)], sensitivity […], specificity […] | C15: Para 3 – results | D15: Q24 | G15: Not started
A16: 12 | B16: Ciprofloxacin ROC-AUC […] | C16: Para 3 – results | D16: Q23 | G16: Not started
... A21: 17 | B21: [Name] and [Title] of signatory | C21: Signature block | D21: IvE office | G21: Not started

Sheet Isolate Table
A1: Master Isolate Table
A2: One row per isolate. Row 5 is an example (partition "Excluded" so it is not counted) – overwrite it with real data. Checks in columns W–Y run automatically.
A4: Isolate ID | B4: BioSample accession | C4: SRA run accession | D4: Assembly accession | E4: Source database | F4: Dataset / BioProject | G4: Species | H4: Country | I4: Collection year | J4: Sample source | K4: AST method | L4: Breakpoint standard | M4: Breakpoint version | N4: Meropenem MIC (mg/L) | O4: Meropenem S/I/R | P4: Ciprofloxacin MIC (mg/L) | Q4: Ciprofloxacin S/I/R | R4: Cefotaxime MIC (mg/L) | S4: Cefotaxime S/I/R | T4: Genome QC pass | U4: SNP cluster / ST | V4: Partition | W4: Kenyan isolate (auto) | X4: Duplicate check (auto) | Y4: Cluster leakage check (auto) | Z4: Notes
A5: EXAMPLE-001 | B5: SAMN00000000 | C5: SRR0000000 | D5: GCA_000000000.1 | E5: NCBI AST Browser | F5: PRJNA000000 | G5: Klebsiella pneumoniae | H5: Kenya | I5: 2019 | J5: Clinical | K5: Broth microdilution | L5: CLSI | M5: M100 Ed34 (2024) | N5: 8 | O5: R | P5: 4 | Q5: R | R5: 64 | S5: R | T5: Yes | U5: ST147 | V5: Excluded | W5: =IF(H5="","",IF(H5="Kenya","Yes","No")) | X5: =IF(B5="","",IF(COUNTIF($B$5:$B$3004,B5)>1,"DUPLICATE","OK")) | Y5: =IF(OR(U5="",V5="",V5="Excluded"),"",IF(COUNTIFS($U$5:$U$3004,U5,$V$5:$V$3004,"<>"&V5,$V$5:$V$3004,"<>",$V$5:$V$3004,"<>Excluded")>0,"LEAK RISK","OK")) | Z5: Example only – fictitious accessions
W6: =IF(H6="","",IF(H6="Kenya","Yes","No")) | X6: =IF(B6="","",IF(COUNTIF($B$5:$B$3004,B6)>1,"DUPLICATE","OK")) | Y6: =IF(OR(U6="",V6="",V6="Excluded"),"",IF(COUNTIFS($U$5:$U$3004,U6,$V$5:$V$3004,"<>"&V6,$V$5:$V$3004,"<>",$V$5:$V$3004,"<>Excluded")>0,"LEAK RISK","OK"))
W7: =IF(H7="","",IF(H7="Kenya","Yes","No")) | X7: =IF(B7="","",IF(COUNTIF($B$5:$B$3004,B7)>1,"DUPLICATE","OK")) | Y7: =IF(OR(U7="",V7="",V7="Excluded"),"",IF(COUNTIFS($U$5:$U$3004,U7,$V$5:$V$3004,"<>"&V7,$V$5:$V$3004,"<>",$V$5:$V$3004,"<>Excluded")>0,"LEAK RISK","OK"))
W8: =IF(H8="","",IF(H8="Kenya","Yes","No")) | X8: =IF(B8="","",IF(COUNTIF($B$5:$B$3004,B8)>1,"DUPLICATE","OK")) | Y8: =IF(OR(U8="",V8="",V8="Excluded"),"",IF(COUNTIFS($U$5:$U$3004,U8,$V$5:$V$3004,"<>"&V8,$V$5:$V$3004,"<>",$V$5:$V$3004,"<>Excluded")>0,"LEAK RISK","OK"))
W9: =IF(H9="","",IF(H9="Kenya","Yes","No")) | X9: =IF(B9="","",IF(COUNTIF($B$5:$B$3004,B9)>1,"DUPLICATE","OK")) | Y9: =IF(OR(U9="",V9="",V9="Excluded"),"",IF(COUNTIFS($U$5:$U$3004,U9,$V$5:$V$3004,"<>"&V9,$V$5:$V$3004,"<>",$V$5:$V$3004,"<>Excluded")>0,"LEAK RISK","OK"))
W10: =IF(H10="","",IF(H10="Kenya","Yes","No")) | X10: =IF(B10="","",IF(COUNTIF($B$5:$B$3004,B10)>1,"DUPLICATE","OK")) | Y10: =IF(OR(U10="",V10="",V10="Excluded"),"",IF(COUNTIFS($U$5:$U$3004,U10,$V$5:$V$3004,"<>"&V10,$V$5:$V$3004,"<>",$V$5:$V$3004,"<>Excluded")>0,"LEAK RISK","OK"))
W11: =IF(H11="","",IF(H11="Kenya","Yes","No")) | X11: =IF(B11="","",IF(COUNTIF($B$5:$B$3004,B11)>1,"DUPLICATE","OK")) | Y11: =IF(OR(U11="",V11="",V11="Excluded"),"",IF(COUNTIFS($U$5:$U$3004,U11,$V$5:$V$3004,"<>"&V11,$V$5:$V$3004,"<>",$V$5:$V$3004,"<>Excluded")>0,"LEAK RISK","OK"))
W12: =IF(H12="","",IF(H12="Kenya","Yes","No")) | X12: =IF(B12="","",IF(COUNTIF($B$5:$B$3004,B12)>1,"DUPLICATE","OK")) | Y12: =IF(OR(U12="",V12="",V12="Excluded"),"",IF(COUNTIFS($U$5:$U$3004,U12,$V$5:$V$3004,"<>"&V12,$V$5:$V$3004,"<>",$V$5:$V$3004,"<>Excluded")>0,"LEAK RISK","OK"))
W13: =IF(H13="","",IF(H13="Kenya","Yes","No")) | X13: =IF(B13="","",IF(COUNTIF($B$5:$B$3004,B13)>1,"DUPLICATE","OK")) | Y13: =IF(OR(U13="",V13="",V13="Excluded"),"",IF(COUNTIFS($U$5:$U$3004,U13,$V$5:$V$3004,"<>"&V13,$V$5:$V$3004,"<>",$V$5:$V$3004,"<>Excluded")>0,"LEAK RISK","OK"))
W14: =IF(H14="","",IF(H14="Kenya","Yes","No")) | X14: =IF(B14="","",IF(COUNTIF($B$5:$B$3004,B14)>1,"DUPLICATE","OK")) | Y14: =IF(OR(U14="",V14="",V14="Excluded"),"",IF(COUNTIFS($U$5:$U$3004,U14,$V$5:$V$3004,"<>"&V14,$V$5:$V$3004,"<>",$V$5:$V$3004,"<>Excluded")>0,"LEAK RISK","OK"))
W15: =IF(H15="","",IF(H15="Kenya","Yes","No")) | X15: =IF(B15="","",IF(COUNTIF($B$5:$B$3004,B15)>1,"DUPLICATE","OK")) | Y15: =IF(OR(U15="",V15="",V15="Excluded"),"",IF(COUNTIFS($U$5:$U$3004,U15,$V$5:$V$3004,"<>"&V15,$V$5:$V$3004,"<>",$V$5:$V$3004,"<>Excluded")>0,"LEAK RISK","OK"))
W16: =IF(H16="","",IF(H16="Kenya","Yes","No")) | X16: =IF(B16="","",IF(COUNTIF($B$5:$B$3004,B16)>1,"DUPLICATE","OK")) | Y16: =IF(OR(U16="",V16="",V16="Excluded"),"",IF(COUNTIFS($U$5:$U$3004,U16,$V$5:$V$3004,"<>"&V16,$V$5:$V$3004,"<>",$V$5:$V$3004,"<>Excluded")>0,"LEAK RISK","OK"))
W17: =IF(H17="","",IF(H17="Kenya","Yes","No")) | X17: =IF(B17="","",IF(COUNTIF($B$5:$B$3004,B17)>1,"DUPLICATE","OK")) | Y17: =IF(OR(U17="",V17="",V17="Excluded"),"",IF(COUNTIFS($U$5:$U$3004,U17,$V$5:$V$3004,"<>"&V17,$V$5:$V$3004,"<>",$V$5:$V$3004,"<>Excluded")>0,"LEAK RISK","OK"))
... W3004: =IF(H3004="","",IF(H3004="Kenya","Yes","No")) | X3004: =IF(B3004="","",IF(COUNTIF($B$5:$B$3004,B3004)>1,"DUPLICATE","OK")) | Y3004: =IF(OR(U3004="",V3004="",V3004="Excluded"),"",IF(COUNTIFS($U$5:$U$3004,U3004,$V$5:$V$3004,"<>"&V3004,$V$5:$V$3004,"<>",$V$5:$V$3004,"<>Excluded")>0,"LEAK RISK","OK"))

Sheet Data Summary
A1: Data Summary (automatic)
A2: Counts calculated from the Isolate Table. Do not type in this sheet. Rows with partition "Excluded" are not counted in partition tables.
A4: 1. Isolates by partition
A5: Partition | B5: Isolates | C5: Kenyan | D5: QC pass | E5: QC fail | F5: Duplicates | G5: Leak risk
A6: Training | B6: =COUNTIF('Isolate Table'!$V$5:$V$3004,A6) | C6: =COUNTIFS('Isolate Table'!$V$5:$V$3004,A6,'Isolate Table'!$H$5:$H$3004,"Kenya") | D6: =COUNTIFS('Isolate Table'!$V$5:$V$3004,A6,'Isolate Table'!$T$5:$T$3004,"Yes") | E6: =COUNTIFS('Isolate Table'!$V$5:$V$3004,A6,'Isolate Table'!$T$5:$T$3004,"No") | F6: =COUNTIFS('Isolate Table'!$V$5:$V$3004,A6,'Isolate Table'!$X$5:$X$3004,"DUPLICATE") | G6: =COUNTIFS('Isolate Table'!$V$5:$V$3004,A6,'Isolate Table'!$Y$5:$Y$3004,"LEAK RISK")
A7: Validation | B7: =COUNTIF('Isolate Table'!$V$5:$V$3004,A7) | C7: =COUNTIFS('Isolate Table'!$V$5:$V$3004,A7,'Isolate Table'!$H$5:$H$3004,"Kenya") | D7: =COUNTIFS('Isolate Table'!$V$5:$V$3004,A7,'Isolate Table'!$T$5:$T$3004,"Yes") | E7: =COUNTIFS('Isolate Table'!$V$5:$V$3004,A7,'Isolate Table'!$T$5:$T$3004,"No") | F7: =COUNTIFS('Isolate Table'!$V$5:$V$3004,A7,'Isolate Table'!$X$5:$X$3004,"DUPLICATE") | G7: =COUNTIFS('Isolate Table'!$V$5:$V$3004,A7,'Isolate Table'!$Y$5:$Y$3004,"LEAK RISK")
A8: Test | B8: =COUNTIF('Isolate Table'!$V$5:$V$3004,A8) | C8: =COUNTIFS('Isolate Table'!$V$5:$V$3004,A8,'Isolate Table'!$H$5:$H$3004,"Kenya") | D8: =COUNTIFS('Isolate Table'!$V$5:$V$3004,A8,'Isolate Table'!$T$5:$T$3004,"Yes") | E8: =COUNTIFS('Isolate Table'!$V$5:$V$3004,A8,'Isolate Table'!$T$5:$T$3004,"No") | F8: =COUNTIFS('Isolate Table'!$V$5:$V$3004,A8,'Isolate Table'!$X$5:$X$3004,"DUPLICATE") | G8: =COUNTIFS('Isolate Table'!$V$5:$V$3004,A8,'Isolate Table'!$Y$5:$Y$3004,"LEAK RISK")
A9: External test | B9: =COUNTIF('Isolate Table'!$V$5:$V$3004,A9) | C9: =COUNTIFS('Isolate Table'!$V$5:$V$3004,A9,'Isolate Table'!$H$5:$H$3004,"Kenya") | D9: =COUNTIFS('Isolate Table'!$V$5:$V$3004,A9,'Isolate Table'!$T$5:$T$3004,"Yes") | E9: =COUNTIFS('Isolate Table'!$V$5:$V$3004,A9,'Isolate Table'!$T$5:$T$3004,"No") | F9: =COUNTIFS('Isolate Table'!$V$5:$V$3004,A9,'Isolate Table'!$X$5:$X$3004,"DUPLICATE") | G9: =COUNTIFS('Isolate Table'!$V$5:$V$3004,A9,'Isolate Table'!$Y$5:$Y$3004,"LEAK RISK")
A10: NPHL locked validation | B10: =COUNTIF('Isolate Table'!$V$5:$V$3004,A10) | C10: =COUNTIFS('Isolate Table'!$V$5:$V$3004,A10,'Isolate Table'!$H$5:$H$3004,"Kenya") | D10: =COUNTIFS('Isolate Table'!$V$5:$V$3004,A10,'Isolate Table'!$T$5:$T$3004,"Yes") | E10: =COUNTIFS('Isolate Table'!$V$5:$V$3004,A10,'Isolate Table'!$T$5:$T$3004,"No") | F10: =COUNTIFS('Isolate Table'!$V$5:$V$3004,A10,'Isolate Table'!$X$5:$X$3004,"DUPLICATE") | G10: =COUNTIFS('Isolate Table'!$V$5:$V$3004,A10,'Isolate Table'!$Y$5:$Y$3004,"LEAK RISK")
A11: Total (excl. Excluded) | B11: =SUM(B6:B10) | C11: =SUM(C6:C10) | D11: =SUM(D6:D10) | E11: =SUM(E6:E10) | F11: =SUM(F6:F10) | G11: =SUM(G6:G10)
A13: 2. Resistance labels by drug and partition
A14: Partition | B14: MEM R | C14: MEM S | D14: MEM I | E14: CIP R | F14: CIP S | G14: CIP I | H14: CTX R | I14: CTX S | J14: CTX I
A15: Training | B15: =COUNTIFS('Isolate Table'!$V$5:$V$3004,$A15,'Isolate Table'!$O$5:$O$3004,"R") | C15: =COUNTIFS('Isolate Table'!$V$5:$V$3004,$A15,'Isolate Table'!$O$5:$O$3004,"S") | D15: =COUNTIFS('Isolate Table'!$V$5:$V$3004,$A15,'Isolate Table'!$O$5:$O$3004,"I") | E15: =COUNTIFS('Isolate Table'!$V$5:$V$3004,$A15,'Isolate Table'!$Q$5:$Q$3004,"R") | F15: =COUNTIFS('Isolate Table'!$V$5:$V$3004,$A15,'Isolate Table'!$Q$5:$Q$3004,"S") | G15: =COUNTIFS('Isolate Table'!$V$5:$V$3004,$A15,'Isolate Table'!$Q$5:$Q$3004,"I") | H15: =COUNTIFS('Isolate Table'!$V$5:$V$3004,$A15,'Isolate Table'!$S$5:$S$3004,"R") | I15: =COUNTIFS('Isolate Table'!$V$5:$V$3004,$A15,'Isolate Table'!$S$5:$S$3004,"S") | J15: =COUNTIFS('Isolate Table'!$V$5:$V$3004,$A15,'Isolate Table'!$S$5:$S$3004,"I")
A16: Validation | B16: =COUNTIFS('Isolate Table'!$V$5:$V$3004,$A16,'Isolate Table'!$O$5:$O$3004,"R") | C16: =COUNTIFS('Isolate Table'!$V$5:$V$3004,$A16,'Isolate Table'!$O$5:$O$3004,"S") | D16: =COUNTIFS('Isolate Table'!$V$5:$V$3004,$A16,'Isolate Table'!$O$5:$O$3004,"I") | E16: =COUNTIFS('Isolate Table'!$V$5:$V$3004,$A16,'Isolate Table'!$Q$5:$Q$3004,"R") | F16: =COUNTIFS('Isolate Table'!$V$5:$V$3004,$A16,'Isolate Table'!$Q$5:$Q$3004,"S") | G16: =COUNTIFS('Isolate Table'!$V$5:$V$3004,$A16,'Isolate Table'!$Q$5:$Q$3004,"I") | H16: =COUNTIFS('Isolate Table'!$V$5:$V$3004,$A16,'Isolate Table'!$S$5:$S$3004,"R") | I16: =COUNTIFS('Isolate Table'!$V$5:$V$3004,$A16,'Isolate Table'!$S$5:$S$3004,"S") | J16: =COUNTIFS('Isolate Table'!$V$5:$V$3004,$A16,'Isolate Table'!$S$5:$S$3004,"I")
A17: Test | B17: =COUNTIFS('Isolate Table'!$V$5:$V$3004,$A17,'Isolate Table'!$O$5:$O$3004,"R") | C17: =COUNTIFS('Isolate Table'!$V$5:$V$3004,$A17,'Isolate Table'!$O$5:$O$3004,"S") | D17: =COUNTIFS('Isolate Table'!$V$5:$V$3004,$A17,'Isolate Table'!$O$5:$O$3004,"I") | E17: =COUNTIFS('Isolate Table'!$V$5:$V$3004,$A17,'Isolate Table'!$Q$5:$Q$3004,"R") | F17: =COUNTIFS('Isolate Table'!$V$5:$V$3004,$A17,'Isolate Table'!$Q$5:$Q$3004,"S") | G17: =COUNTIFS('Isolate Table'!$V$5:$V$3004,$A17,'Isolate Table'!$Q$5:$Q$3004,"I") | H17: =COUNTIFS('Isolate Table'!$V$5:$V$3004,$A17,'Isolate Table'!$S$5:$S$3004,"R") | I17: =COUNTIFS('Isolate Table'!$V$5:$V$3004,$A17,'Isolate Table'!$S$5:$S$3004,"S") | J17: =COUNTIFS('Isolate Table'!$V$5:$V$3004,$A17,'Isolate Table'!$S$5:$S$3004,"I")
A18: External test | B18: =COUNTIFS('Isolate Table'!$V$5:$V$3004,$A18,'Isolate Table'!$O$5:$O$3004,"R") | C18: =COUNTIFS('Isolate Table'!$V$5:$V$3004,$A18,'Isolate Table'!$O$5:$O$3004,"S") | D18: =COUNTIFS('Isolate Table'!$V$5:$V$3004,$A18,'Isolate Table'!$O$5:$O$3004,"I") | E18: =COUNTIFS('Isolate Table'!$V$5:$V$3004,$A18,'Isolate Table'!$Q$5:$Q$3004,"R") | F18: =COUNTIFS('Isolate Table'!$V$5:$V$3004,$A18,'Isolate Table'!$Q$5:$Q$3004,"S") | G18: =COUNTIFS('Isolate Table'!$V$5:$V$3004,$A18,'Isolate Table'!$Q$5:$Q$3004,"I") | H18: =COUNTIFS('Isolate Table'!$V$5:$V$3004,$A18,'Isolate Table'!$S$5:$S$3004,"R") | I18: =COUNTIFS('Isolate Table'!$V$5:$V$3004,$A18,'Isolate Table'!$S$5:$S$3004,"S") | J18: =COUNTIFS('Isolate Table'!$V$5:$V$3004,$A18,'Isolate Table'!$S$5:$S$3004,"I")
A19: NPHL locked validation | B19: =COUNTIFS('Isolate Table'!$V$5:$V$3004,$A19,'Isolate Table'!$O$5:$O$3004,"R") | C19: =COUNTIFS('Isolate Table'!$V$5:$V$3004,$A19,'Isolate Table'!$O$5:$O$3004,"S") | D19: =COUNTIFS('Isolate Table'!$V$5:$V$3004,$A19,'Isolate Table'!$O$5:$O$3004,"I") | E19: =COUNTIFS('Isolate Table'!$V$5:$V$3004,$A19,'Isolate Table'!$Q$5:$Q$3004,"R") | F19: =COUNTIFS('Isolate Table'!$V$5:$V$3004,$A19,'Isolate Table'!$Q$5:$Q$3004,"S") | G19: =COUNTIFS('Isolate Table'!$V$5:$V$3004,$A19,'Isolate Table'!$Q$5:$Q$3004,"I") | H19: =COUNTIFS('Isolate Table'!$V$5:$V$3004,$A19,'Isolate Table'!$S$5:$S$3004,"R") | I19: =COUNTIFS('Isolate Table'!$V$5:$V$3004,$A19,'Isolate Table'!$S$5:$S$3004,"S") | J19: =COUNTIFS('Isolate Table'!$V$5:$V$3004,$A19,'Isolate Table'!$S$5:$S$3004,"I")
A21: 3. Data quality checks
A22: Rows with data but no BioSample | B22: =SUMPRODUCT(('Isolate Table'!$A$5:$A$3004<>"")*('Isolate Table'!$B$5:$B$3004=""))
A23: Duplicate BioSample rows | B23: =COUNTIF('Isolate Table'!$X$5:$X$3004,"DUPLICATE")
A24: Isolates at cluster leakage risk | B24: =COUNTIF('Isolate Table'!$Y$5:$Y$3004,"LEAK RISK")
A25: Overall status | B25: =IF(SUM(B22:B24)=0,"No issues detected",SUM(B22:B24)&" issue(s) – review Isolate Table")
A26: Breakpoint standards in use (rows) | B26: ="CLSI: "&COUNTIF('Isolate Table'!$L$5:$L$3004,"CLSI")&" | EUCAST: "&COUNTIF('Isolate Table'!$L$5:$L$3004,"EUCAST")&" | Other/unknown: "&(COUNTIF('Isolate Table'!$L$5:$L$3004,"Other")+COUNTIF('Isolate Table'!$L$5:$L$3004,"Unknown"))
A28: 4. Isolates by species and partition
A29: Species | B29: Training | C29: Validation | D29: Test | E29: External test | F29: NPHL locked validation | G29: Total
A30: Escherichia coli | B30: =COUNTIFS('Isolate Table'!$G$5:$G$3004,$A30,'Isolate Table'!$V$5:$V$3004,B$29) | C30: =COUNTIFS('Isolate Table'!$G$5:$G$3004,$A30,'Isolate Table'!$V$5:$V$3004,C$29) | D30: =COUNTIFS('Isolate Table'!$G$5:$G$3004,$A30,'Isolate Table'!$V$5:$V$3004,D$29) | E30: =COUNTIFS('Isolate Table'!$G$5:$G$3004,$A30,'Isolate Table'!$V$5:$V$3004,E$29) | F30: =COUNTIFS('Isolate Table'!$G$5:$G$3004,$A30,'Isolate Table'!$V$5:$V$3004,F$29) | G30: =SUM(B30:F30)
A31: Klebsiella pneumoniae | B31: =COUNTIFS('Isolate Table'!$G$5:$G$3004,$A31,'Isolate Table'!$V$5:$V$3004,B$29) | C31: =COUNTIFS('Isolate Table'!$G$5:$G$3004,$A31,'Isolate Table'!$V$5:$V$3004,C$29) | D31: =COUNTIFS('Isolate Table'!$G$5:$G$3004,$A31,'Isolate Table'!$V$5:$V$3004,D$29) | E31: =COUNTIFS('Isolate Table'!$G$5:$G$3004,$A31,'Isolate Table'!$V$5:$V$3004,E$29) | F31: =COUNTIFS('Isolate Table'!$G$5:$G$3004,$A31,'Isolate Table'!$V$5:$V$3004,F$29) | G31: =SUM(B31:F31)
A32: Acinetobacter baumannii | B32: =COUNTIFS('Isolate Table'!$G$5:$G$3004,$A32,'Isolate Table'!$V$5:$V$3004,B$29) | C32: =COUNTIFS('Isolate Table'!$G$5:$G$3004,$A32,'Isolate Table'!$V$5:$V$3004,C$29) | D32: =COUNTIFS('Isolate Table'!$G$5:$G$3004,$A32,'Isolate Table'!$V$5:$V$3004,D$29) | E32: =COUNTIFS('Isolate Table'!$G$5:$G$3004,$A32,'Isolate Table'!$V$5:$V$3004,E$29) | F32: =COUNTIFS('Isolate Table'!$G$5:$G$3004,$A32,'Isolate Table'!$V$5:$V$3004,F$29) | G32: =SUM(B32:F32)
A33: Pseudomonas aeruginosa | B33: =COUNTIFS('Isolate Table'!$G$5:$G$3004,$A33,'Isolate Table'!$V$5:$V$3004,B$29) | C33: =COUNTIFS('Isolate Table'!$G$5:$G$3004,$A33,'Isolate Table'!$V$5:$V$3004,C$29) | D33: =COUNTIFS('Isolate Table'!$G$5:$G$3004,$A33,'Isolate Table'!$V$5:$V$3004,D$29) | E33: =COUNTIFS('Isolate Table'!$G$5:$G$3004,$A33,'Isolate Table'!$V$5:$V$3004,E$29) | F33: =COUNTIFS('Isolate Table'!$G$5:$G$3004,$A33,'Isolate Table'!$V$5:$V$3004,F$29) | G33: =SUM(B33:F33)
A34: Enterobacter cloacae complex | B34: =COUNTIFS('Isolate Table'!$G$5:$G$3004,$A34,'Isolate Table'!$V$5:$V$3004,B$29) | C34: =COUNTIFS('Isolate Table'!$G$5:$G$3004,$A34,'Isolate Table'!$V$5:$V$3004,C$29) | D34: =COUNTIFS('Isolate Table'!$G$5:$G$3004,$A34,'Isolate Table'!$V$5:$V$3004,D$29) | E34: =COUNTIFS('Isolate Table'!$G$5:$G$3004,$A34,'Isolate Table'!$V$5:$V$3004,E$29) | F34: =COUNTIFS('Isolate Table'!$G$5:$G$3004,$A34,'Isolate Table'!$V$5:$V$3004,F$29) | G34: =SUM(B34:F34)
A35: Salmonella enterica | B35: =COUNTIFS('Isolate Table'!$G$5:$G$3004,$A35,'Isolate Table'!$V$5:$V$3004,B$29) | C35: =COUNTIFS('Isolate Table'!$G$5:$G$3004,$A35,'Isolate Table'!$V$5:$V$3004,C$29) | D35: =COUNTIFS('Isolate Table'!$G$5:$G$3004,$A35,'Isolate Table'!$V$5:$V$3004,D$29) | E35: =COUNTIFS('Isolate Table'!$G$5:$G$3004,$A35,'Isolate Table'!$V$5:$V$3004,E$29) | F35: =COUNTIFS('Isolate Table'!$G$5:$G$3004,$A35,'Isolate Table'!$V$5:$V$3004,F$29) | G35: =SUM(B35:F35)
A36: Other | B36: =COUNTIFS('Isolate Table'!$G$5:$G$3004,$A36,'Isolate Table'!$V$5:$V$3004,B$29) | C36: =COUNTIFS('Isolate Table'!$G$5:$G$3004,$A36,'Isolate Table'!$V$5:$V$3004,C$29) | D36: =COUNTIFS('Isolate Table'!$G$5:$G$3004,$A36,'Isolate Table'!$V$5:$V$3004,D$29) | E36: =COUNTIFS('Isolate Table'!$G$5:$G$3004,$A36,'Isolate Table'!$V$5:$V$3004,E$29) | F36: =COUNTIFS('Isolate Table'!$G$5:$G$3004,$A36,'Isolate Table'!$V$5:$V$3004,F$29) | G36: =SUM(B36:F36)

Sheet Model Results
A1: Model Results per Drug
A2: Enter confusion-matrix counts (yellow). Resistant is the positive class. Metrics, Wilson 95% CIs and error rates calculate automatically.
A3: Assumptions
A4: z for 95% CI | B4: 1.96 | C4: Standard normal value for a two-sided 95% confidence interval.
A5: Very major error target (max) | B5: 0.015 | C5: Commonly used acceptance target for AST device evaluations (e.g., FDA/CLSI M52 practice). Confirm the target with NPHL.
A6: Major error target (max) | B6: 0.03 | C6: Commonly used acceptance target for AST device evaluations (e.g., FDA/CLSI M52 practice). Confirm the target with NPHL.
A8: Drug | B8: Evaluation | C8: Dataset / description | D8: Test isolates resistant: predicted R (TP) | E8: Resistant: predicted S (FN) | F8: Susceptible: predicted S (TN) | G8: Susceptible: predicted R (FP) | H8: Decision threshold | I8: AUROC (from analysis) | J8: AUPRC | K8: AUROC stated in letter | L8: Difference vs letter | M8: Total isolates | N8: Sensitivity | O8: Sens. 95% CI low | P8: Sens. 95% CI high | Q8: Specificity | R8: Spec. 95% CI low | S8: Spec. 95% CI high | T8: Balanced accuracy | U8: Categorical agreement | V8: Very major error rate | W8: Major error rate | X8: VME within target? | Y8: ME within target? | Z8: Notes
A9: Meropenem | B9: Internal test – original split (as reported in letter) | K9: 0.952 | L9: =IF(OR(K9="",I9=""),"",I9-K9) | M9: =IF(COUNT(D9:G9)=0,"",SUM(D9:G9)) | N9: =IF((D9+E9)=0,"",D9/(D9+E9)) | O9: =IF((D9+E9)=0,"",((D9/(D9+E9))+$B$4^2/(2*(D9+E9))-$B$4*SQRT((D9/(D9+E9))*(1-(D9/(D9+E9)))/(D9+E9)+$B$4^2/(4*(D9+E9)^2)))/(1+$B$4^2/(D9+E9))) | P9: =IF((D9+E9)=0,"",((D9/(D9+E9))+$B$4^2/(2*(D9+E9))+$B$4*SQRT((D9/(D9+E9))*(1-(D9/(D9+E9)))/(D9+E9)+$B$4^2/(4*(D9+E9)^2)))/(1+$B$4^2/(D9+E9))) | Q9: =IF((F9+G9)=0,"",F9/(F9+G9)) | R9: =IF((F9+G9)=0,"",((F9/(F9+G9))+$B$4^2/(2*(F9+G9))-$B$4*SQRT((F9/(F9+G9))*(1-(F9/(F9+G9)))/(F9+G9)+$B$4^2/(4*(F9+G9)^2)))/(1+$B$4^2/(F9+G9))) | S9: =IF((F9+G9)=0,"",((F9/(F9+G9))+$B$4^2/(2*(F9+G9))+$B$4*SQRT((F9/(F9+G9))*(1-(F9/(F9+G9)))/(F9+G9)+$B$4^2/(4*(F9+G9)^2)))/(1+$B$4^2/(F9+G9))) | T9: =IF(OR(N9="",Q9=""),"",(N9+Q9)/2) | U9: =IF(SUM(D9:G9)=0,"",(D9+F9)/SUM(D9:G9)) | V9: =IF((D9+E9)=0,"",E9/(D9+E9)) | W9: =IF((F9+G9)=0,"",G9/(F9+G9)) | X9: =IF(V9="","",IF(V9<=$B$5,"Yes","No")) | Y9: =IF(W9="","",IF(W9<=$B$6,"Yes","No"))
A10: Meropenem | B10: Internal test – relatedness-aware split | L10: =IF(OR(K10="",I10=""),"",I10-K10) | M10: =IF(COUNT(D10:G10)=0,"",SUM(D10:G10)) | N10: =IF((D10+E10)=0,"",D10/(D10+E10)) | O10: =IF((D10+E10)=0,"",((D10/(D10+E10))+$B$4^2/(2*(D10+E10))-$B$4*SQRT((D10/(D10+E10))*(1-(D10/(D10+E10)))/(D10+E10)+$B$4^2/(4*(D10+E10)^2)))/(1+$B$4^2/(D10+E10))) | P10: =IF((D10+E10)=0,"",((D10/(D10+E10))+$B$4^2/(2*(D10+E10))+$B$4*SQRT((D10/(D10+E10))*(1-(D10/(D10+E10)))/(D10+E10)+$B$4^2/(4*(D10+E10)^2)))/(1+$B$4^2/(D10+E10))) | Q10: =IF((F10+G10)=0,"",F10/(F10+G10)) | R10: =IF((F10+G10)=0,"",((F10/(F10+G10))+$B$4^2/(2*(F10+G10))-$B$4*SQRT((F10/(F10+G10))*(1-(F10/(F10+G10)))/(F10+G10)+$B$4^2/(4*(F10+G10)^2)))/(1+$B$4^2/(F10+G10))) | S10: =IF((F10+G10)=0,"",((F10/(F10+G10))+$B$4^2/(2*(F10+G10))+$B$4*SQRT((F10/(F10+G10))*(1-(F10/(F10+G10)))/(F10+G10)+$B$4^2/(4*(F10+G10)^2)))/(1+$B$4^2/(F10+G10))) | T10: =IF(OR(N10="",Q10=""),"",(N10+Q10)/2) | U10: =IF(SUM(D10:G10)=0,"",(D10+F10)/SUM(D10:G10)) | V10: =IF((D10+E10)=0,"",E10/(D10+E10)) | W10: =IF((F10+G10)=0,"",G10/(F10+G10)) | X10: =IF(V10="","",IF(V10<=$B$5,"Yes","No")) | Y10: =IF(W10="","",IF(W10<=$B$6,"Yes","No"))
A11: Meropenem | B11: External public dataset | L11: =IF(OR(K11="",I11=""),"",I11-K11) | M11: =IF(COUNT(D11:G11)=0,"",SUM(D11:G11)) | N11: =IF((D11+E11)=0,"",D11/(D11+E11)) | O11: =IF((D11+E11)=0,"",((D11/(D11+E11))+$B$4^2/(2*(D11+E11))-$B$4*SQRT((D11/(D11+E11))*(1-(D11/(D11+E11)))/(D11+E11)+$B$4^2/(4*(D11+E11)^2)))/(1+$B$4^2/(D11+E11))) | P11: =IF((D11+E11)=0,"",((D11/(D11+E11))+$B$4^2/(2*(D11+E11))+$B$4*SQRT((D11/(D11+E11))*(1-(D11/(D11+E11)))/(D11+E11)+$B$4^2/(4*(D11+E11)^2)))/(1+$B$4^2/(D11+E11))) | Q11: =IF((F11+G11)=0,"",F11/(F11+G11)) | R11: =IF((F11+G11)=0,"",((F11/(F11+G11))+$B$4^2/(2*(F11+G11))-$B$4*SQRT((F11/(F11+G11))*(1-(F11/(F11+G11)))/(F11+G11)+$B$4^2/(4*(F11+G11)^2)))/(1+$B$4^2/(F11+G11))) | S11: =IF((F11+G11)=0,"",((F11/(F11+G11))+$B$4^2/(2*(F11+G11))+$B$4*SQRT((F11/(F11+G11))*(1-(F11/(F11+G11)))/(F11+G11)+$B$4^2/(4*(F11+G11)^2)))/(1+$B$4^2/(F11+G11))) | T11: =IF(OR(N11="",Q11=""),"",(N11+Q11)/2) | U11: =IF(SUM(D11:G11)=0,"",(D11+F11)/SUM(D11:G11)) | V11: =IF((D11+E11)=0,"",E11/(D11+E11)) | W11: =IF((F11+G11)=0,"",G11/(F11+G11)) | X11: =IF(V11="","",IF(V11<=$B$5,"Yes","No")) | Y11: =IF(W11="","",IF(W11<=$B$6,"Yes","No"))
A12: Meropenem | B12: Rule-based baseline (AMRFinderPlus/ResFinder) | L12: =IF(OR(K12="",I12=""),"",I12-K12) | M12: =IF(COUNT(D12:G12)=0,"",SUM(D12:G12)) | N12: =IF((D12+E12)=0,"",D12/(D12+E12)) | O12: =IF((D12+E12)=0,"",((D12/(D12+E12))+$B$4^2/(2*(D12+E12))-$B$4*SQRT((D12/(D12+E12))*(1-(D12/(D12+E12)))/(D12+E12)+$B$4^2/(4*(D12+E12)^2)))/(1+$B$4^2/(D12+E12))) | P12: =IF((D12+E12)=0,"",((D12/(D12+E12))+$B$4^2/(2*(D12+E12))+$B$4*SQRT((D12/(D12+E12))*(1-(D12/(D12+E12)))/(D12+E12)+$B$4^2/(4*(D12+E12)^2)))/(1+$B$4^2/(D12+E12))) | Q12: =IF((F12+G12)=0,"",F12/(F12+G12)) | R12: =IF((F12+G12)=0,"",((F12/(F12+G12))+$B$4^2/(2*(F12+G12))-$B$4*SQRT((F12/(F12+G12))*(1-(F12/(F12+G12)))/(F12+G12)+$B$4^2/(4*(F12+G12)^2)))/(1+$B$4^2/(F12+G12))) | S12: =IF((F12+G12)=0,"",((F12/(F12+G12))+$B$4^2/(2*(F12+G12))+$B$4*SQRT((F12/(F12+G12))*(1-(F12/(F12+G12)))/(F12+G12)+$B$4^2/(4*(F12+G12)^2)))/(1+$B$4^2/(F12+G12))) | T12: =IF(OR(N12="",Q12=""),"",(N12+Q12)/2) | U12: =IF(SUM(D12:G12)=0,"",(D12+F12)/SUM(D12:G12)) | V12: =IF((D12+E12)=0,"",E12/(D12+E12)) | W12: =IF((F12+G12)=0,"",G12/(F12+G12)) | X12: =IF(V12="","",IF(V12<=$B$5,"Yes","No")) | Y12: =IF(W12="","",IF(W12<=$B$6,"Yes","No"))
A13: Meropenem | B13: NPHL validation (locked set) | L13: =IF(OR(K13="",I13=""),"",I13-K13) | M13: =IF(COUNT(D13:G13)=0,"",SUM(D13:G13)) | N13: =IF((D13+E13)=0,"",D13/(D13+E13)) | O13: =IF((D13+E13)=0,"",((D13/(D13+E13))+$B$4^2/(2*(D13+E13))-$B$4*SQRT((D13/(D13+E13))*(1-(D13/(D13+E13)))/(D13+E13)+$B$4^2/(4*(D13+E13)^2)))/(1+$B$4^2/(D13+E13))) | P13: =IF((D13+E13)=0,"",((D13/(D13+E13))+$B$4^2/(2*(D13+E13))+$B$4*SQRT((D13/(D13+E13))*(1-(D13/(D13+E13)))/(D13+E13)+$B$4^2/(4*(D13+E13)^2)))/(1+$B$4^2/(D13+E13))) | Q13: =IF((F13+G13)=0,"",F13/(F13+G13)) | R13: =IF((F13+G13)=0,"",((F13/(F13+G13))+$B$4^2/(2*(F13+G13))-$B$4*SQRT((F13/(F13+G13))*(1-(F13/(F13+G13)))/(F13+G13)+$B$4^2/(4*(F13+G13)^2)))/(1+$B$4^2/(F13+G13))) | S13: =IF((F13+G13)=0,"",((F13/(F13+G13))+$B$4^2/(2*(F13+G13))+$B$4*SQRT((F13/(F13+G13))*(1-(F13/(F13+G13)))/(F13+G13)+$B$4^2/(4*(F13+G13)^2)))/(1+$B$4^2/(F13+G13))) | T13: =IF(OR(N13="",Q13=""),"",(N13+Q13)/2) | U13: =IF(SUM(D13:G13)=0,"",(D13+F13)/SUM(D13:G13)) | V13: =IF((D13+E13)=0,"",E13/(D13+E13)) | W13: =IF((F13+G13)=0,"",G13/(F13+G13)) | X13: =IF(V13="","",IF(V13<=$B$5,"Yes","No")) | Y13: =IF(W13="","",IF(W13<=$B$6,"Yes","No"))
A14: Ciprofloxacin | B14: Internal test – original split (as reported in letter) | K14: 0.872 | L14: =IF(OR(K14="",I14=""),"",I14-K14) | M14: =IF(COUNT(D14:G14)=0,"",SUM(D14:G14)) | N14: =IF((D14+E14)=0,"",D14/(D14+E14)) | O14: =IF((D14+E14)=0,"",((D14/(D14+E14))+$B$4^2/(2*(D14+E14))-$B$4*SQRT((D14/(D14+E14))*(1-(D14/(D14+E14)))/(D14+E14)+$B$4^2/(4*(D14+E14)^2)))/(1+$B$4^2/(D14+E14))) | P14: =IF((D14+E14)=0,"",((D14/(D14+E14))+$B$4^2/(2*(D14+E14))+$B$4*SQRT((D14/(D14+E14))*(1-(D14/(D14+E14)))/(D14+E14)+$B$4^2/(4*(D14+E14)^2)))/(1+$B$4^2/(D14+E14))) | Q14: =IF((F14+G14)=0,"",F14/(F14+G14)) | R14: =IF((F14+G14)=0,"",((F14/(F14+G14))+$B$4^2/(2*(F14+G14))-$B$4*SQRT((F14/(F14+G14))*(1-(F14/(F14+G14)))/(F14+G14)+$B$4^2/(4*(F14+G14)^2)))/(1+$B$4^2/(F14+G14))) | S14: =IF((F14+G14)=0,"",((F14/(F14+G14))+$B$4^2/(2*(F14+G14))+$B$4*SQRT((F14/(F14+G14))*(1-(F14/(F14+G14)))/(F14+G14)+$B$4^2/(4*(F14+G14)^2)))/(1+$B$4^2/(F14+G14))) | T14: =IF(OR(N14="",Q14=""),"",(N14+Q14)/2) | U14: =IF(SUM(D14:G14)=0,"",(D14+F14)/SUM(D14:G14)) | V14: =IF((D14+E14)=0,"",E14/(D14+E14)) | W14: =IF((F14+G14)=0,"",G14/(F14+G14)) | X14: =IF(V14="","",IF(V14<=$B$5,"Yes","No")) | Y14: =IF(W14="","",IF(W14<=$B$6,"Yes","No"))
A15: Ciprofloxacin | B15: Internal test – relatedness-aware split | L15: =IF(OR(K15="",I15=""),"",I15-K15) | M15: =IF(COUNT(D15:G15)=0,"",SUM(D15:G15)) | N15: =IF((D15+E15)=0,"",D15/(D15+E15)) | O15: =IF((D15+E15)=0,"",((D15/(D15+E15))+$B$4^2/(2*(D15+E15))-$B$4*SQRT((D15/(D15+E15))*(1-(D15/(D15+E15)))/(D15+E15)+$B$4^2/(4*(D15+E15)^2)))/(1+$B$4^2/(D15+E15))) | P15: =IF((D15+E15)=0,"",((D15/(D15+E15))+$B$4^2/(2*(D15+E15))+$B$4*SQRT((D15/(D15+E15))*(1-(D15/(D15+E15)))/(D15+E15)+$B$4^2/(4*(D15+E15)^2)))/(1+$B$4^2/(D15+E15))) | Q15: =IF((F15+G15)=0,"",F15/(F15+G15)) | R15: =IF((F15+G15)=0,"",((F15/(F15+G15))+$B$4^2/(2*(F15+G15))-$B$4*SQRT((F15/(F15+G15))*(1-(F15/(F15+G15)))/(F15+G15)+$B$4^2/(4*(F15+G15)^2)))/(1+$B$4^2/(F15+G15))) | S15: =IF((F15+G15)=0,"",((F15/(F15+G15))+$B$4^2/(2*(F15+G15))+$B$4*SQRT((F15/(F15+G15))*(1-(F15/(F15+G15)))/(F15+G15)+$B$4^2/(4*(F15+G15)^2)))/(1+$B$4^2/(F15+G15))) | T15: =IF(OR(N15="",Q15=""),"",(N15+Q15)/2) | U15: =IF(SUM(D15:G15)=0,"",(D15+F15)/SUM(D15:G15)) | V15: =IF((D15+E15)=0,"",E15/(D15+E15)) | W15: =IF((F15+G15)=0,"",G15/(F15+G15)) | X15: =IF(V15="","",IF(V15<=$B$5,"Yes","No")) | Y15: =IF(W15="","",IF(W15<=$B$6,"Yes","No"))
A16: Ciprofloxacin | B16: External public dataset | L16: =IF(OR(K16="",I16=""),"",I16-K16) | M16: =IF(COUNT(D16:G16)=0,"",SUM(D16:G16)) | N16: =IF((D16+E16)=0,"",D16/(D16+E16)) | O16: =IF((D16+E16)=0,"",((D16/(D16+E16))+$B$4^2/(2*(D16+E16))-$B$4*SQRT((D16/(D16+E16))*(1-(D16/(D16+E16)))/(D16+E16)+$B$4^2/(4*(D16+E16)^2)))/(1+$B$4^2/(D16+E16))) | P16: =IF((D16+E16)=0,"",((D16/(D16+E16))+$B$4^2/(2*(D16+E16))+$B$4*SQRT((D16/(D16+E16))*(1-(D16/(D16+E16)))/(D16+E16)+$B$4^2/(4*(D16+E16)^2)))/(1+$B$4^2/(D16+E16))) | Q16: =IF((F16+G16)=0,"",F16/(F16+G16)) | R16: =IF((F16+G16)=0,"",((F16/(F16+G16))+$B$4^2/(2*(F16+G16))-$B$4*SQRT((F16/(F16+G16))*(1-(F16/(F16+G16)))/(F16+G16)+$B$4^2/(4*(F16+G16)^2)))/(1+$B$4^2/(F16+G16))) | S16: =IF((F16+G16)=0,"",((F16/(F16+G16))+$B$4^2/(2*(F16+G16))+$B$4*SQRT((F16/(F16+G16))*(1-(F16/(F16+G16)))/(F16+G16)+$B$4^2/(4*(F16+G16)^2)))/(1+$B$4^2/(F16+G16))) | T16: =IF(OR(N16="",Q16=""),"",(N16+Q16)/2) | U16: =IF(SUM(D16:G16)=0,"",(D16+F16)/SUM(D16:G16)) | V16: =IF((D16+E16)=0,"",E16/(D16+E16)) | W16: =IF((F16+G16)=0,"",G16/(F16+G16)) | X16: =IF(V16="","",IF(V16<=$B$5,"Yes","No")) | Y16: =IF(W16="","",IF(W16<=$B$6,"Yes","No"))
A17: Ciprofloxacin | B17: Rule-based baseline (AMRFinderPlus/ResFinder) | L17: =IF(OR(K17="",I17=""),"",I17-K17) | M17: =IF(COUNT(D17:G17)=0,"",SUM(D17:G17)) | N17: =IF((D17+E17)=0,"",D17/(D17+E17)) | O17: =IF((D17+E17)=0,"",((D17/(D17+E17))+$B$4^2/(2*(D17+E17))-$B$4*SQRT((D17/(D17+E17))*(1-(D17/(D17+E17)))/(D17+E17)+$B$4^2/(4*(D17+E17)^2)))/(1+$B$4^2/(D17+E17))) | P17: =IF((D17+E17)=0,"",((D17/(D17+E17))+$B$4^2/(2*(D17+E17))+$B$4*SQRT((D17/(D17+E17))*(1-(D17/(D17+E17)))/(D17+E17)+$B$4^2/(4*(D17+E17)^2)))/(1+$B$4^2/(D17+E17))) | Q17: =IF((F17+G17)=0,"",F17/(F17+G17)) | R17: =IF((F17+G17)=0,"",((F17/(F17+G17))+$B$4^2/(2*(F17+G17))-$B$4*SQRT((F17/(F17+G17))*(1-(F17/(F17+G17)))/(F17+G17)+$B$4^2/(4*(F17+G17)^2)))/(1+$B$4^2/(F17+G17))) | S17: =IF((F17+G17)=0,"",((F17/(F17+G17))+$B$4^2/(2*(F17+G17))+$B$4*SQRT((F17/(F17+G17))*(1-(F17/(F17+G17)))/(F17+G17)+$B$4^2/(4*(F17+G17)^2)))/(1+$B$4^2/(F17+G17))) | T17: =IF(OR(N17="",Q17=""),"",(N17+Q17)/2) | U17: =IF(SUM(D17:G17)=0,"",(D17+F17)/SUM(D17:G17)) | V17: =IF((D17+E17)=0,"",E17/(D17+E17)) | W17: =IF((F17+G17)=0,"",G17/(F17+G17)) | X17: =IF(V17="","",IF(V17<=$B$5,"Yes","No")) | Y17: =IF(W17="","",IF(W17<=$B$6,"Yes","No"))
A18: Ciprofloxacin | B18: NPHL validation (locked set) | L18: =IF(OR(K18="",I18=""),"",I18-K18) | M18: =IF(COUNT(D18:G18)=0,"",SUM(D18:G18)) | N18: =IF((D18+E18)=0,"",D18/(D18+E18)) | O18: =IF((D18+E18)=0,"",((D18/(D18+E18))+$B$4^2/(2*(D18+E18))-$B$4*SQRT((D18/(D18+E18))*(1-(D18/(D18+E18)))/(D18+E18)+$B$4^2/(4*(D18+E18)^2)))/(1+$B$4^2/(D18+E18))) | P18: =IF((D18+E18)=0,"",((D18/(D18+E18))+$B$4^2/(2*(D18+E18))+$B$4*SQRT((D18/(D18+E18))*(1-(D18/(D18+E18)))/(D18+E18)+$B$4^2/(4*(D18+E18)^2)))/(1+$B$4^2/(D18+E18))) | Q18: =IF((F18+G18)=0,"",F18/(F18+G18)) | R18: =IF((F18+G18)=0,"",((F18/(F18+G18))+$B$4^2/(2*(F18+G18))-$B$4*SQRT((F18/(F18+G18))*(1-(F18/(F18+G18)))/(F18+G18)+$B$4^2/(4*(F18+G18)^2)))/(1+$B$4^2/(F18+G18))) | S18: =IF((F18+G18)=0,"",((F18/(F18+G18))+$B$4^2/(2*(F18+G18))+$B$4*SQRT((F18/(F18+G18))*(1-(F18/(F18+G18)))/(F18+G18)+$B$4^2/(4*(F18+G18)^2)))/(1+$B$4^2/(F18+G18))) | T18: =IF(OR(N18="",Q18=""),"",(N18+Q18)/2) | U18: =IF(SUM(D18:G18)=0,"",(D18+F18)/SUM(D18:G18)) | V18: =IF((D18+E18)=0,"",E18/(D18+E18)) | W18: =IF((F18+G18)=0,"",G18/(F18+G18)) | X18: =IF(V18="","",IF(V18<=$B$5,"Yes","No")) | Y18: =IF(W18="","",IF(W18<=$B$6,"Yes","No"))
